Workbook

Sheet Total Boardings (All Days)
A1: Total All Days Boardings by Station
I2: Fiscal Year 2010 | U2: Fiscal Year 2011 | AG2: Fiscal Year 2012 | AS2: Fiscal Year 2013 | BE2: Fiscal Year 2014 | BQ2: Fiscal Year 2015 | CC2: Fiscal Year 2016 | CO2: Fiscal Year 2017 | DA2: Fiscal Year 2018 | DM2: Fiscal Year 2019 | DY2: Fiscal Year 2020 | EK2: Fiscal Year 2021 | EW2: Fiscal Year 2022 | FI2: Fiscal Year 2023 | FU2: Fiscal Year 2024
B3: 39783 | C3: 39814 | D3: 39845 | E3: 39873 | F3: 39904 | G3: 39934 | H3: 39965 | I3: 39995 | J3: 40026 | K3: 40057 | L3: 40087 | M3: 40118 | N3: 40148 | O3: 40179 | P3: 40210 | Q3: 40238 | R3: 40269 | S3: 40299 | T3: 40330 | U3: 40360 | V3: 40391 | W3: 40422 | X3: 40452 | Y3: 40483 | Z3: 40513 | AA3: 40544 | AB3: 40575 | AC3: 40603 | AD3: 40634 | AE3: 40664 | AF3: 40695 | AG3: 40725 | AH3: 40756 | AI3: 40787 | AJ3: 40817 | AK3: 40848 | AL3: 40878 | AM3: 40909 | AN3: 40940 | AO3: 40969 | AP3: 41000 | AQ3: 41030 | AR3: 41061 | AS3: 41091 | AT3: 41122 | AU3: 41153 | AV3: 41183 | AW3: 41214 | AX3: 41244 | AY3: 41275 | AZ3: 41306 | BA3: 41334 | BB3: 41365 | BC3: 41395 | BD3: 41426 | BE3: 41456 | BF3: 41487 | BG3: 41518 | BH3: 41548 | BI3: 41579 | BJ3: 41609 | BK3: 41640 | BL3: 41671 | BM3: 41699 | BN3: 41730 | BO3: 41760 | BP3: 41791 | BQ3: 41821 | BR3: 41852 | BS3: 41883 | BT3: 41913 | BU3: 41944 | BV3: 41974 | BW3: 42005 | BX3: 42036 | BY3: 42064 | BZ3: 42095 | CA3: 42125 | CB3: 42156 | CC3: 42186 | CD3: 42217 | CE3: 42248 | CF3: 42278 | CG3: 42309 | CH3: 42339 | CI3: 42370 | CJ3: 42401 | CK3: 42430 | CL3: 42461 | CM3: 42491 | CN3: 42522 | CO3: 42552 | CP3: 42583 | CQ3: 42614 | CR3: 42644 | CS3: 42675 | CT3: 42705 | CU3: 42736 | CV3: 42767 | CW3: 42795 | CX3: 42826 | CY3: 42856 | CZ3: 42887 | DA3: 42917 | DB3: 42948 | DC3: 42979 | DD3: 43009 | DE3: 43040 | DF3: 43070 | DG3: 43101 | DH3: 43132 | DI3: 43160 | DJ3: 43191 | DK3: 43221 | DL3: 43252 | DM3: 43282 | DN3: 43313 | DO3: 43344 | DP3: 43374 | DQ3: 43405 | DR3: 43435 | DS3: 43466 | DT3: 43497 | DU3: 43525 | DV3: 43556 | DW3: 43586 | DX3: 43617 | DY3: 43647 | DZ3: 43678 | EA3: 43709 | EB3: 43739 | EC3: 43770 | ED3: 43800 | EE3: 43831 | EF3: 43862 | EG3: 43891 | EH3: 43922 | EI3: 43952 | EJ3: 43983 | EK3: 44013 | EL3: 44044 | EM3: 44075 | EN3: 44105 | EO3: 44136 | EP3: 44166 | EQ3: 44197 | ER3: 44228 | ES3: 44256 | ET3: 44287 | EU3: 44317 | EV3: 44348 | EW3: 44378 | EX3: 44409 | EY3: 44440 | EZ3: 44470 | FA3: 44501 | FB3: 44531 | FC3: 44562 | FD3: 44593 | FE3: 44621 | FF3: 44652 | FG3: 44682 | FH3: 44713 | FI3: 45130 | FJ3: 45161 | FK3: 45192 | FL3: 45222 | FM3: 45253 | FN3: 45283 | FO3: 44949 | FP3: 44980 | FQ3: 45008 | FR3: 45039 | FS3: 45069 | FT3: 45100 | FU3: 45130 | FV3: 45161 | FW3: 45192 | FX3: 45222 | FY3: 45253 | FZ3: 45283 | GA3: 45315 | GB3: 45345 | GC3: 45374 | GD3: 45405 | GE3: 45435 | GF3: 45466 | GG3: 45496 | GH3: 45527 | GI3: 45558 | GJ3: 45589 | GK3: 45621 | GL3: 45652
A4: Metro Parkway | GA4: 11083 | GB4: 44308 | GC4: 42866 | GD4: 43111 | GE4: 44473 | GF4: 39597 | GG4: 47415 | GH4: 48788 | GI4: 14386 | GJ4: 50614 | GK4: 41214 | GL4: 45889
A5: Mountain View/ 25th Ave | GA5: 723 | GB5: 3314 | GC5: 3567 | GD5: 3671 | GE5: 3053 | GF5: 3123 | GG5: 3590 | GH5: 4215 | GI5: 817 | GJ5: 4779 | GK5: 4450 | GL5: 4062
A6: 25th Ave/ Dunlap | GA6: 853 | GB6: 5212 | GC6: 5345 | GD6: 4747 | GE6: 4758 | GF6: 4921 | GG6: 5436 | GH6: 5803 | GI6: 1285 | GJ6: 6103 | GK6: 5663 | GL6: 5333
A7: 19th Ave/Dunlap | CK7: ='Total Weekday Boardings'!CK7+'Total Saturday Boardings'!CK7+'Total Sunday-Holiday Boardings'!CK7 -> 27298 | CL7: ='Total Weekday Boardings'!CL7+'Total Saturday Boardings'!CL7+'Total Sunday-Holiday Boardings'!CL7 -> 67999 | CM7: ='Total Weekday Boardings'!CM7+'Total Saturday Boardings'!CM7+'Total Sunday-Holiday Boardings'!CM7 -> 68443 | CN7: ='Total Weekday Boardings'!CN7+'Total Saturday Boardings'!CN7+'Total Sunday-Holiday Boardings'!CN7 -> 72729 | CO7: ='Total Weekday Boardings'!CO7+'Total Saturday Boardings'!CO7+'Total Sunday-Holiday Boardings'!CO7 -> 73104 | CP7: ='Total Weekday Boardings'!CP7+'Total Saturday Boardings'!CP7+'Total Sunday-Holiday Boardings'!CP7 -> 76486 | CQ7: ='Total Weekday Boardings'!CQ7+'Total Saturday Boardings'!CQ7+'Total Sunday-Holiday Boardings'!CQ7 -> 71411 | CR7: ='Total Weekday Boardings'!CR7+'Total Saturday Boardings'!CR7+'Total Sunday-Holiday Boardings'!CR7 -> 73609 | ... DX7: ='Total Weekday Boardings'!DX7+'Total Saturday Boardings'!DX7+'Total Sunday-Holiday Boardings'!DX7 -> 77369 | DY7: 80910 | DZ7: 83989 | EA7: 80707 | EB7: 83567 | EC7: 79743 | ED7: 82625 | EE7: 87424 | EF7: 84653 | EG7: 75943 | EH7: 53796 | EI7: 51399 | EJ7: 46702 | EK7: 46630 | EL7: 49579 | EM7: 46407 | EN7: 46740 | EO7: 44020 | EP7: 38128 | EQ7: 20398 | ER7: 40369 | ES7: 43711 | ET7: 43106 | EU7: 41041 | EV7: 42686 | EW7: 44020 | EX7: 44022 | EY7: 42411 | EZ7: 44274 | FA7: 42479 | FB7: 47653 | FC7: 45019 | FD7: 49644 | FE7: 54135 | FF7: 49501 | FG7: =SUM('Total Weekday Boardings'!FG7,'Total Saturday Boardings'!FG7,'Total Sunday-Holiday Boardings'!FG7) -> 49413 | FH7: =SUM('Total Weekday Boardings'!FH7,'Total Saturday Boardings'!FH7,'Total Sunday-Holiday Boardings'!FH7) -> 43940 | FI7: =SUM('Total Weekday Boardings'!FI7,'Total Saturday Boardings'!FI7,'Total Sunday-Holiday Boardings'!FI7) -> 48704 | FJ7: =SUM('Total Weekday Boardings'!FJ7,'Total Saturday Boardings'!FJ7,'Total Sunday-Holiday Boardings'!FJ7) -> 52082 | FK7: =SUM('Total Weekday Boardings'!FK7,'Total Saturday Boardings'!FK7,'Total Sunday-Holiday Boardings'!FK7) -> 55589.25 | FL7: =SUM('Total Weekday Boardings'!FL7,'Total Saturday Boardings'!FL7,'Total Sunday-Holiday Boardings'!FL7) -> 51752 | FM7: =SUM('Total Weekday Boardings'!FM7,'Total Saturday Boardings'!FM7,'Total Sunday-Holiday Boardings'!FM7) -> 46394 | FN7: =SUM('Total Weekday Boardings'!FN7,'Total Saturday Boardings'!FN7,'Total Sunday-Holiday Boardings'!FN7) -> 47045 | ... FT7: =SUM('Total Weekday Boardings'!FT7,'Total Saturday Boardings'!FT7,'Total Sunday-Holiday Boardings'!FT7) -> 48405 | FU7: 54856 | FV7: 59459 | FW7: 50005 | FX7: 58785 | FY7: 57620 | FZ7: 60197 | GA7: 60466 | GB7: 26228 | GC7: 29108 | GD7: 23807 | GE7: 23773 | GF7: 23027 | GG7: 23385 | GH7: 24467 | GI7: 65140 | GJ7: 23613 | GK7: 26113 | GL7: 21309
A8: Northern/19th Ave | CK8: ='Total Weekday Boardings'!CK8+'Total Saturday Boardings'!CK8+'Total Sunday-Holiday Boardings'!CK8 -> 10425 | CL8: ='Total Weekday Boardings'!CL8+'Total Saturday Boardings'!CL8+'Total Sunday-Holiday Boardings'!CL8 -> 27077 | CM8: ='Total Weekday Boardings'!CM8+'Total Saturday Boardings'!CM8+'Total Sunday-Holiday Boardings'!CM8 -> 28876 | CN8: ='Total Weekday Boardings'!CN8+'Total Saturday Boardings'!CN8+'Total Sunday-Holiday Boardings'!CN8 -> 28590 | CO8: ='Total Weekday Boardings'!CO8+'Total Saturday Boardings'!CO8+'Total Sunday-Holiday Boardings'!CO8 -> 29426 | CP8: ='Total Weekday Boardings'!CP8+'Total Saturday Boardings'!CP8+'Total Sunday-Holiday Boardings'!CP8 -> 31329 | CQ8: ='Total Weekday Boardings'!CQ8+'Total Saturday Boardings'!CQ8+'Total Sunday-Holiday Boardings'!CQ8 -> 29818 | CR8: ='Total Weekday Boardings'!CR8+'Total Saturday Boardings'!CR8+'Total Sunday-Holiday Boardings'!CR8 -> 31794 | ... DX8: ='Total Weekday Boardings'!DX8+'Total Saturday Boardings'!DX8+'Total Sunday-Holiday Boardings'!DX8 -> 29380 | DY8: 28882 | DZ8: 29945 | EA8: 29286 | EB8: 32968 | EC8: 31369 | ED8: 31623 | EE8: 32689 | EF8: 31753 | EG8: 27567 | EH8: 18000 | EI8: 18082 | EJ8: 16335 | EK8: 14825 | EL8: 15016 | EM8: 14790 | EN8: 15995 | EO8: 13923 | EP8: 12339 | EQ8: 7199 | ER8: 12432 | ES8: 14296 | ET8: 14715 | EU8: 13474 | EV8: 13571 | EW8: 13923 | EX8: 15314 | EY8: 14812 | EZ8: 16545 | FA8: 17228 | FB8: 17780 | FC8: 16091 | FD8: 18952 | FE8: 21921 | FF8: 19832 | FG8: =SUM('Total Weekday Boardings'!FG8,'Total Saturday Boardings'!FG8,'Total Sunday-Holiday Boardings'!FG8) -> 19944 | FH8: =SUM('Total Weekday Boardings'!FH8,'Total Saturday Boardings'!FH8,'Total Sunday-Holiday Boardings'!FH8) -> 15920 | FI8: =SUM('Total Weekday Boardings'!FI8,'Total Saturday Boardings'!FI8,'Total Sunday-Holiday Boardings'!FI8) -> 16779 | FJ8: =SUM('Total Weekday Boardings'!FJ8,'Total Saturday Boardings'!FJ8,'Total Sunday-Holiday Boardings'!FJ8) -> 18881 | FK8: =SUM('Total Weekday Boardings'!FK8,'Total Saturday Boardings'!FK8,'Total Sunday-Holiday Boardings'!FK8) -> 21040.75 | FL8: =SUM('Total Weekday Boardings'!FL8,'Total Saturday Boardings'!FL8,'Total Sunday-Holiday Boardings'!FL8) -> 21141 | FM8: =SUM('Total Weekday Boardings'!FM8,'Total Saturday Boardings'!FM8,'Total Sunday-Holiday Boardings'!FM8) -> 18709 | FN8: =SUM('Total Weekday Boardings'!FN8,'Total Saturday Boardings'!FN8,'Total Sunday-Holiday Boardings'!FN8) -> 19521 | ... FT8: =SUM('Total Weekday Boardings'!FT8,'Total Saturday Boardings'!FT8,'Total Sunday-Holiday Boardings'!FT8) -> 20667 | FU8: 21801 | FV8: 23482 | FW8: 21991 | FX8: 23223 | FY8: 21722 | FZ8: 20664 | GA8: 21426 | GB8: 21047 | GC8: 21478 | GD8: 19581 | GE8: 20179 | GF8: 18519 | GG8: 18478 | GH8: 20892 | GI8: 20599 | GJ8: 21171 | GK8: 19703 | GL8: 19767
A9: Glendale/19th Ave | CK9: ='Total Weekday Boardings'!CK9+'Total Saturday Boardings'!CK9+'Total Sunday-Holiday Boardings'!CK9 -> 13359 | CL9: ='Total Weekday Boardings'!CL9+'Total Saturday Boardings'!CL9+'Total Sunday-Holiday Boardings'!CL9 -> 35197 | CM9: ='Total Weekday Boardings'!CM9+'Total Saturday Boardings'!CM9+'Total Sunday-Holiday Boardings'!CM9 -> 37287 | CN9: ='Total Weekday Boardings'!CN9+'Total Saturday Boardings'!CN9+'Total Sunday-Holiday Boardings'!CN9 -> 36936 | CO9: ='Total Weekday Boardings'!CO9+'Total Saturday Boardings'!CO9+'Total Sunday-Holiday Boardings'!CO9 -> 38666 | CP9: ='Total Weekday Boardings'!CP9+'Total Saturday Boardings'!CP9+'Total Sunday-Holiday Boardings'!CP9 -> 41437 | CQ9: ='Total Weekday Boardings'!CQ9+'Total Saturday Boardings'!CQ9+'Total Sunday-Holiday Boardings'!CQ9 -> 40226 | CR9: ='Total Weekday Boardings'!CR9+'Total Saturday Boardings'!CR9+'Total Sunday-Holiday Boardings'!CR9 -> 42707 | ... DX9: ='Total Weekday Boardings'!DX9+'Total Saturday Boardings'!DX9+'Total Sunday-Holiday Boardings'!DX9 -> 34819 | DY9: 34729 | DZ9: 37346 | EA9: 37387 | EB9: 42082 | EC9: 40001 | ED9: 38108 | EE9: 39219 | EF9: 38257 | EG9: 33480 | EH9: 22623 | EI9: 21647 | EJ9: 19289 | EK9: 18479 | EL9: 18660 | EM9: 18930 | EN9: 21037 | EO9: 17082 | EP9: 15724 | EQ9: 9346 | ER9: 16330 | ES9: 18647 | ET9: 18813 | EU9: 17751 | EV9: 17017 | EW9: 17082 | EX9: 19138 | EY9: 19284 | EZ9: 21504 | FA9: 20691 | FB9: 21800 | FC9: 20486 | FD9: 23754 | FE9: 27253 | FF9: 25143 | FG9: =SUM('Total Weekday Boardings'!FG9,'Total Saturday Boardings'!FG9,'Total Sunday-Holiday Boardings'!FG9) -> 24541 | FH9: =SUM('Total Weekday Boardings'!FH9,'Total Saturday Boardings'!FH9,'Total Sunday-Holiday Boardings'!FH9) -> 20459 | FI9: =SUM('Total Weekday Boardings'!FI9,'Total Saturday Boardings'!FI9,'Total Sunday-Holiday Boardings'!FI9) -> 20842 | FJ9: =SUM('Total Weekday Boardings'!FJ9,'Total Saturday Boardings'!FJ9,'Total Sunday-Holiday Boardings'!FJ9) -> 25262 | FK9: =SUM('Total Weekday Boardings'!FK9,'Total Saturday Boardings'!FK9,'Total Sunday-Holiday Boardings'!FK9) -> 28210 | FL9: =SUM('Total Weekday Boardings'!FL9,'Total Saturday Boardings'!FL9,'Total Sunday-Holiday Boardings'!FL9) -> 27561 | FM9: =SUM('Total Weekday Boardings'!FM9,'Total Saturday Boardings'!FM9,'Total Sunday-Holiday Boardings'!FM9) -> 26105 | FN9: =SUM('Total Weekday Boardings'!FN9,'Total Saturday Boardings'!FN9,'Total Sunday-Holiday Boardings'!FN9) -> 26779 | ... FT9: =SUM('Total Weekday Boardings'!FT9,'Total Saturday Boardings'!FT9,'Total Sunday-Holiday Boardings'!FT9) -> 25882 | FU9: 26959 | FV9: 30591 | FW9: 28201 | FX9: 28462 | FY9: 27454 | FZ9: 27009 | GA9: 27023 | GB9: 25950 | GC9: 28048 | GD9: 25911 | GE9: 27133 | GF9: 24615 | GG9: 25213 | GH9: 24821 | GI9: 24440 | GJ9: 24608 | GK9: 23428 | GL9: 23084
A10: 19th Ave/Montebello | C10: ='Total Weekday Boardings'!C10+'Total Saturday Boardings'!C10+'Total Sunday-Holiday Boardings'!C10 -> 105501 | D10: ='Total Weekday Boardings'!D10+'Total Saturday Boardings'!D10+'Total Sunday-Holiday Boardings'!D10 -> 100135 | E10: ='Total Weekday Boardings'!E10+'Total Saturday Boardings'!E10+'Total Sunday-Holiday Boardings'!E10 -> 105219 | F10: ='Total Weekday Boardings'!F10+'Total Saturday Boardings'!F10+'Total Sunday-Holiday Boardings'!F10 -> 100192 | G10: ='Total Weekday Boardings'!G10+'Total Saturday Boardings'!G10+'Total Sunday-Holiday Boardings'!G10 -> 92987 | H10: ='Total Weekday Boardings'!H10+'Total Saturday Boardings'!H10+'Total Sunday-Holiday Boardings'!H10 -> 81670 | I10: ='Total Weekday Boardings'!I10+'Total Saturday Boardings'!I10+'Total Sunday-Holiday Boardings'!I10 -> 71978 | J10: ='Total Weekday Boardings'!J10+'Total Saturday Boardings'!J10+'Total Sunday-Holiday Boardings'!J10 -> 75508 | ... DX10: ='Total Weekday Boardings'!DX10+'Total Saturday Boardings'!DX10+'Total Sunday-Holiday Boardings'!DX10 -> 47070 | DY10: 45509 | DZ10: 53391 | EA10: 50087 | EB10: 55122 | EC10: 53001 | ED10: 51837 | EE10: 50588 | EF10: 50534 | EG10: 42815 | EH10: 27190 | EI10: 28417 | EJ10: 25730 | EK10: 23166 | EL10: 23162 | EM10: 23243 | EN10: 25257 | EO10: 22407 | EP10: 18730 | EQ10: 10970 | ER10: 19638 | ES10: 22774 | ET10: 25077 | EU10: 23079 | EV10: 21693 | EW10: 22407 | EX10: 24545 | EY10: 24840 | EZ10: 27698 | FA10: 28260 | FB10: 30447 | FC10: 27108 | FD10: 31452 | FE10: 37039 | FF10: 35588 | FG10: =SUM('Total Weekday Boardings'!FG10,'Total Saturday Boardings'!FG10,'Total Sunday-Holiday Boardings'!FG10) -> 34670 | FH10: =SUM('Total Weekday Boardings'!FH10,'Total Saturday Boardings'!FH10,'Total Sunday-Holiday Boardings'!FH10) -> 27208 | FI10: =SUM('Total Weekday Boardings'!FI10,'Total Saturday Boardings'!FI10,'Total Sunday-Holiday Boardings'!FI10) -> 28828 | FJ10: =SUM('Total Weekday Boardings'!FJ10,'Total Saturday Boardings'!FJ10,'Total Sunday-Holiday Boardings'!FJ10) -> 33956 | FK10: =SUM('Total Weekday Boardings'!FK10,'Total Saturday Boardings'!FK10,'Total Sunday-Holiday Boardings'!FK10) -> 38418.75 | FL10: =SUM('Total Weekday Boardings'!FL10,'Total Saturday Boardings'!FL10,'Total Sunday-Holiday Boardings'!FL10) -> 38591 | FM10: =SUM('Total Weekday Boardings'!FM10,'Total Saturday Boardings'!FM10,'Total Sunday-Holiday Boardings'!FM10) -> 35759 | FN10: =SUM('Total Weekday Boardings'!FN10,'Total Saturday Boardings'!FN10,'Total Sunday-Holiday Boardings'!FN10) -> 37366 | ... FT10: =SUM('Total Weekday Boardings'!FT10,'Total Saturday Boardings'!FT10,'Total Sunday-Holiday Boardings'!FT10) -> 33121 | FU10: 30699 | FV10: 34558 | FW10: 32673 | FX10: 34879 | FY10: 32080 | FZ10: 33062 | GA10: 32711 | GB10: 32619 | GC10: 33921 | GD10: 31658 | GE10: 32270 | GF10: 27983 | GG10: 27073 | GH10: 32159 | GI10: 31676 | GJ10: 32461 | GK10: 30599 | GL10: 30452
A11: 19th Ave/Camelback | C11: ='Total Weekday Boardings'!C11+'Total Saturday Boardings'!C11+'Total Sunday-Holiday Boardings'!C11 -> 23894 | D11: ='Total Weekday Boardings'!D11+'Total Saturday Boardings'!D11+'Total Sunday-Holiday Boardings'!D11 -> 26718 | E11: ='Total Weekday Boardings'!E11+'Total Saturday Boardings'!E11+'Total Sunday-Holiday Boardings'!E11 -> 28117 | F11: ='Total Weekday Boardings'!F11+'Total Saturday Boardings'!F11+'Total Sunday-Holiday Boardings'!F11 -> 31309 | G11: ='Total Weekday Boardings'!G11+'Total Saturday Boardings'!G11+'Total Sunday-Holiday Boardings'!G11 -> 28034 | H11: ='Total Weekday Boardings'!H11+'Total Saturday Boardings'!H11+'Total Sunday-Holiday Boardings'!H11 -> 28010 | I11: ='Total Weekday Boardings'!I11+'Total Saturday Boardings'!I11+'Total Sunday-Holiday Boardings'!I11 -> 29828 | J11: ='Total Weekday Boardings'!J11+'Total Saturday Boardings'!J11+'Total Sunday-Holiday Boardings'!J11 -> 33215 | ... DX11: ='Total Weekday Boardings'!DX11+'Total Saturday Boardings'!DX11+'Total Sunday-Holiday Boardings'!DX11 -> 44136 | DY11: 42949 | DZ11: 50078 | EA11: 50225 | EB11: 54803 | EC11: 50159 | ED11: 47624 | EE11: 49261 | EF11: 49403 | EG11: 38673 | EH11: 23224 | EI11: 23556 | EJ11: 21272 | EK11: 20358 | EL11: 21255 | EM11: 21425 | EN11: 23268 | EO11: 19724 | EP11: 16146 | EQ11: 9343 | ER11: 17391 | ES11: 20097 | ET11: 21747 | EU11: 20197 | EV11: 19778 | EW11: 19724 | EX11: 24101 | EY11: 23733 | EZ11: 24431 | FA11: 25885 | FB11: 26015 | FC11: 23735 | FD11: 27448 | FE11: 31476 | FF11: 29927 | FG11: =SUM('Total Weekday Boardings'!FG11,'Total Saturday Boardings'!FG11,'Total Sunday-Holiday Boardings'!FG11) -> 28174 | FH11: =SUM('Total Weekday Boardings'!FH11,'Total Saturday Boardings'!FH11,'Total Sunday-Holiday Boardings'!FH11) -> 22357 | FI11: =SUM('Total Weekday Boardings'!FI11,'Total Saturday Boardings'!FI11,'Total Sunday-Holiday Boardings'!FI11) -> 22997 | FJ11: =SUM('Total Weekday Boardings'!FJ11,'Total Saturday Boardings'!FJ11,'Total Sunday-Holiday Boardings'!FJ11) -> 28632 | FK11: =SUM('Total Weekday Boardings'!FK11,'Total Saturday Boardings'!FK11,'Total Sunday-Holiday Boardings'!FK11) -> 33111.5 | FL11: =SUM('Total Weekday Boardings'!FL11,'Total Saturday Boardings'!FL11,'Total Sunday-Holiday Boardings'!FL11) -> 32040 | FM11: =SUM('Total Weekday Boardings'!FM11,'Total Saturday Boardings'!FM11,'Total Sunday-Holiday Boardings'!FM11) -> 30146 | FN11: =SUM('Total Weekday Boardings'!FN11,'Total Saturday Boardings'!FN11,'Total Sunday-Holiday Boardings'!FN11) -> 30659 | ... FT11: =SUM('Total Weekday Boardings'!FT11,'Total Saturday Boardings'!FT11,'Total Sunday-Holiday Boardings'!FT11) -> 32360 | FU11: 31293 | FV11: 36079 | FW11: 33956 | FX11: 35443 | FY11: 33041 | FZ11: 32207 | GA11: 34558 | GB11: 34731 | GC11: 33960 | GD11: 31792 | GE11: 31577 | GF11: 27899 | GG11: 27826 | GH11: 33744 | GI11: 34342 | GJ11: 34562 | GK11: 32197 | GL11: 30487
A12: 7th Ave/Camelback | C12: ='Total Weekday Boardings'!C12+'Total Saturday Boardings'!C12+'Total Sunday-Holiday Boardings'!C12 -> 14536 | D12: ='Total Weekday Boardings'!D12+'Total Saturday Boardings'!D12+'Total Sunday-Holiday Boardings'!D12 -> 19165 | E12: ='Total Weekday Boardings'!E12+'Total Saturday Boardings'!E12+'Total Sunday-Holiday Boardings'!E12 -> 17225 | F12: ='Total Weekday Boardings'!F12+'Total Saturday Boardings'!F12+'Total Sunday-Holiday Boardings'!F12 -> 19240 | G12: ='Total Weekday Boardings'!G12+'Total Saturday Boardings'!G12+'Total Sunday-Holiday Boardings'!G12 -> 19308 | H12: ='Total Weekday Boardings'!H12+'Total Saturday Boardings'!H12+'Total Sunday-Holiday Boardings'!H12 -> 16860 | I12: ='Total Weekday Boardings'!I12+'Total Saturday Boardings'!I12+'Total Sunday-Holiday Boardings'!I12 -> 18462 | J12: ='Total Weekday Boardings'!J12+'Total Saturday Boardings'!J12+'Total Sunday-Holiday Boardings'!J12 -> 20535 | ... DX12: ='Total Weekday Boardings'!DX12+'Total Saturday Boardings'!DX12+'Total Sunday-Holiday Boardings'!DX12 -> 23616 | DY12: 23566 | DZ12: 26851 | EA12: 26671 | EB12: 27727 | EC12: 24428 | ED12: 23095 | EE12: 24818 | EF12: 23627 | EG12: 19074 | EH12: 12316 | EI12: 13121 | EJ12: 11094 | EK12: 10245 | EL12: 10580 | EM12: 10914 | EN12: 11345 | EO12: 10828 | EP12: 8358 | EQ12: 4613 | ER12: 8926 | ES12: 11152 | ET12: 12271 | EU12: 11203 | EV12: 11238 | EW12: 10828 | EX12: 13735 | EY12: 13910 | EZ12: 14094 | FA12: 15160 | FB12: 14521 | FC12: 13135 | FD12: 15136 | FE12: 18109 | FF12: 17044 | FG12: =SUM('Total Weekday Boardings'!FG12,'Total Saturday Boardings'!FG12,'Total Sunday-Holiday Boardings'!FG12) -> 16406 | FH12: =SUM('Total Weekday Boardings'!FH12,'Total Saturday Boardings'!FH12,'Total Sunday-Holiday Boardings'!FH12) -> 12764 | FI12: =SUM('Total Weekday Boardings'!FI12,'Total Saturday Boardings'!FI12,'Total Sunday-Holiday Boardings'!FI12) -> 13466 | FJ12: =SUM('Total Weekday Boardings'!FJ12,'Total Saturday Boardings'!FJ12,'Total Sunday-Holiday Boardings'!FJ12) -> 15963 | FK12: =SUM('Total Weekday Boardings'!FK12,'Total Saturday Boardings'!FK12,'Total Sunday-Holiday Boardings'!FK12) -> 17713 | FL12: =SUM('Total Weekday Boardings'!FL12,'Total Saturday Boardings'!FL12,'Total Sunday-Holiday Boardings'!FL12) -> 16727 | FM12: =SUM('Total Weekday Boardings'!FM12,'Total Saturday Boardings'!FM12,'Total Sunday-Holiday Boardings'!FM12) -> 15793 | FN12: =SUM('Total Weekday Boardings'!FN12,'Total Saturday Boardings'!FN12,'Total Sunday-Holiday Boardings'!FN12) -> 15501 | ... FT12: =SUM('Total Weekday Boardings'!FT12,'Total Saturday Boardings'!FT12,'Total Sunday-Holiday Boardings'!FT12) -> 16330 | FU12: 15727 | FV12: 18504 | FW12: 18148 | FX12: 19503 | FY12: 17671 | FZ12: 16736 | GA12: 18803 | GB12: 18834 | GC12: 18807 | GD12: 18448 | GE12: 17954 | GF12: 15430 | GG12: 14748 | GH12: 17845 | GI12: 17670 | GJ12: 16891 | GK12: 15918 | GL12: 16167
A13: Central Ave/Camelback | C13: ='Total Weekday Boardings'!C13+'Total Saturday Boardings'!C13+'Total Sunday-Holiday Boardings'!C13 -> 24091 | D13: ='Total Weekday Boardings'!D13+'Total Saturday Boardings'!D13+'Total Sunday-Holiday Boardings'!D13 -> 20320 | E13: ='Total Weekday Boardings'!E13+'Total Saturday Boardings'!E13+'Total Sunday-Holiday Boardings'!E13 -> 17061 | F13: ='Total Weekday Boardings'!F13+'Total Saturday Boardings'!F13+'Total Sunday-Holiday Boardings'!F13 -> 16820 | G13: ='Total Weekday Boardings'!G13+'Total Saturday Boardings'!G13+'Total Sunday-Holiday Boardings'!G13 -> 14184 | H13: ='Total Weekday Boardings'!H13+'Total Saturday Boardings'!H13+'Total Sunday-Holiday Boardings'!H13 -> 11599 | I13: ='Total Weekday Boardings'!I13+'Total Saturday Boardings'!I13+'Total Sunday-Holiday Boardings'!I13 -> 11373 | J13: ='Total Weekday Boardings'!J13+'Total Saturday Boardings'!J13+'Total Sunday-Holiday Boardings'!J13 -> 11477 | ... DX13: ='Total Weekday Boardings'!DX13+'Total Saturday Boardings'!DX13+'Total Sunday-Holiday Boardings'!DX13 -> 20614 | DY13: 18647 | DZ13: 21470 | EA13: 21851 | EB13: 23143 | EC13: 22344 | ED13: 20808 | EE13: 21017 | EF13: 20822 | EG13: 15024 | EH13: 7821 | EI13: 8013 | EJ13: 7735 | EK13: 7392 | EL13: 7680 | EM13: 7870 | EN13: 8830 | EO13: 8929 | EP13: 6594 | EQ13: 3833 | ER13: 7050 | ES13: 8595 | ET13: 9507 | EU13: 8977 | EV13: 9074 | EW13: 8929 | EX13: 10101 | EY13: 9754 | EZ13: 10804 | FA13: 11525 | FB13: 12378 | FC13: 9974 | FD13: 11607 | FE13: 14713 | FF13: 13623 | FG13: =SUM('Total Weekday Boardings'!FG13,'Total Saturday Boardings'!FG13,'Total Sunday-Holiday Boardings'!FG13) -> 13333 | FH13: =SUM('Total Weekday Boardings'!FH13,'Total Saturday Boardings'!FH13,'Total Sunday-Holiday Boardings'!FH13) -> 9635 | FI13: =SUM('Total Weekday Boardings'!FI13,'Total Saturday Boardings'!FI13,'Total Sunday-Holiday Boardings'!FI13) -> 10506 | FJ13: =SUM('Total Weekday Boardings'!FJ13,'Total Saturday Boardings'!FJ13,'Total Sunday-Holiday Boardings'!FJ13) -> 11149 | FK13: =SUM('Total Weekday Boardings'!FK13,'Total Saturday Boardings'!FK13,'Total Sunday-Holiday Boardings'!FK13) -> 12627.25 | FL13: =SUM('Total Weekday Boardings'!FL13,'Total Saturday Boardings'!FL13,'Total Sunday-Holiday Boardings'!FL13) -> 12935 | FM13: =SUM('Total Weekday Boardings'!FM13,'Total Saturday Boardings'!FM13,'Total Sunday-Holiday Boardings'!FM13) -> 12847 | FN13: =SUM('Total Weekday Boardings'!FN13,'Total Saturday Boardings'!FN13,'Total Sunday-Holiday Boardings'!FN13) -> 12986 | ... FT13: =SUM('Total Weekday Boardings'!FT13,'Total Saturday Boardings'!FT13,'Total Sunday-Holiday Boardings'!FT13) -> 13809 | FU13: 13224 | FV13: 14477 | FW13: 13980 | FX13: 17233 | FY13: 14333 | FZ13: 15497 | GA13: 14766 | GB13: 15051 | GC13: 15327 | GD13: 14932 | GE13: 14211 | GF13: 12542 | GG13: 12118 | GH13: 13054 | GI13: 13550 | GJ13: 13436 | GK13: 13361 | GL13: 13944
A14: Campbell/Central Ave | C14: ='Total Weekday Boardings'!C14+'Total Saturday Boardings'!C14+'Total Sunday-Holiday Boardings'!C14 -> 16279 | D14: ='Total Weekday Boardings'!D14+'Total Saturday Boardings'!D14+'Total Sunday-Holiday Boardings'!D14 -> 21604 | E14: ='Total Weekday Boardings'!E14+'Total Saturday Boardings'!E14+'Total Sunday-Holiday Boardings'!E14 -> 19583 | F14: ='Total Weekday Boardings'!F14+'Total Saturday Boardings'!F14+'Total Sunday-Holiday Boardings'!F14 -> 22885 | G14: ='Total Weekday Boardings'!G14+'Total Saturday Boardings'!G14+'Total Sunday-Holiday Boardings'!G14 -> 15669 | H14: ='Total Weekday Boardings'!H14+'Total Saturday Boardings'!H14+'Total Sunday-Holiday Boardings'!H14 -> 9305 | I14: ='Total Weekday Boardings'!I14+'Total Saturday Boardings'!I14+'Total Sunday-Holiday Boardings'!I14 -> 13790 | J14: ='Total Weekday Boardings'!J14+'Total Saturday Boardings'!J14+'Total Sunday-Holiday Boardings'!J14 -> 13758 | ... DX14: ='Total Weekday Boardings'!DX14+'Total Saturday Boardings'!DX14+'Total Sunday-Holiday Boardings'!DX14 -> 14233 | DY14: 11134 | DZ14: 26783 | EA14: 27555 | EB14: 27243 | EC14: 25439 | ED14: 21513 | EE14: 25994 | EF14: 24186 | EG14: 12110 | EH14: 4368 | EI14: 4946 | EJ14: 4416 | EK14: 4176 | EL14: 4654 | EM14: 5034 | EN14: 5789 | EO14: 5377 | EP14: 4067 | EQ14: 2279 | ER14: 4073 | ES14: 6060 | ET14: 10416 | EU14: 8185 | EV14: 6754 | EW14: 5377 | EX14: 16540 | EY14: 16549 | EZ14: 14221 | FA14: 15261 | FB14: 11497 | FC14: 11959 | FD14: 14618 | FE14: 16546 | FF14: 15065 | FG14: =SUM('Total Weekday Boardings'!FG14,'Total Saturday Boardings'!FG14,'Total Sunday-Holiday Boardings'!FG14) -> 13211 | FH14: =SUM('Total Weekday Boardings'!FH14,'Total Saturday Boardings'!FH14,'Total Sunday-Holiday Boardings'!FH14) -> 6439 | FI14: =SUM('Total Weekday Boardings'!FI14,'Total Saturday Boardings'!FI14,'Total Sunday-Holiday Boardings'!FI14) -> 5061 | FJ14: =SUM('Total Weekday Boardings'!FJ14,'Total Saturday Boardings'!FJ14,'Total Sunday-Holiday Boardings'!FJ14) -> 13285 | FK14: =SUM('Total Weekday Boardings'!FK14,'Total Saturday Boardings'!FK14,'Total Sunday-Holiday Boardings'!FK14) -> 15405.5 | FL14: =SUM('Total Weekday Boardings'!FL14,'Total Saturday Boardings'!FL14,'Total Sunday-Holiday Boardings'!FL14) -> 13494 | FM14: =SUM('Total Weekday Boardings'!FM14,'Total Saturday Boardings'!FM14,'Total Sunday-Holiday Boardings'!FM14) -> 14149 | FN14: =SUM('Total Weekday Boardings'!FN14,'Total Saturday Boardings'!FN14,'Total Sunday-Holiday Boardings'!FN14) -> 11906 | ... FT14: =SUM('Total Weekday Boardings'!FT14,'Total Saturday Boardings'!FT14,'Total Sunday-Holiday Boardings'!FT14) -> 8429 | FU14: 6293 | FV14: 14053 | FW14: 15336 | FX14: 14921 | FY14: 16268 | FZ14: 12901 | GA14: 14589 | GB14: 16568 | GC14: 13785 | GD14: 15559 | GE14: 14143 | GF14: 7465 | GG14: 6106 | GH14: 16677 | GI14: 16602 | GJ14: 15353 | GK14: 15777 | GL14: 13347
A15: Indian School/Central Ave | C15: ='Total Weekday Boardings'!C15+'Total Saturday Boardings'!C15+'Total Sunday-Holiday Boardings'!C15 -> 28791 | D15: ='Total Weekday Boardings'!D15+'Total Saturday Boardings'!D15+'Total Sunday-Holiday Boardings'!D15 -> 32042 | E15: ='Total Weekday Boardings'!E15+'Total Saturday Boardings'!E15+'Total Sunday-Holiday Boardings'!E15 -> 32721 | F15: ='Total Weekday Boardings'!F15+'Total Saturday Boardings'!F15+'Total Sunday-Holiday Boardings'!F15 -> 38658 | G15: ='Total Weekday Boardings'!G15+'Total Saturday Boardings'!G15+'Total Sunday-Holiday Boardings'!G15 -> 32875 | H15: ='Total Weekday Boardings'!H15+'Total Saturday Boardings'!H15+'Total Sunday-Holiday Boardings'!H15 -> 25212 | I15: ='Total Weekday Boardings'!I15+'Total Saturday Boardings'!I15+'Total Sunday-Holiday Boardings'!I15 -> 32429 | J15: ='Total Weekday Boardings'!J15+'Total Saturday Boardings'!J15+'Total Sunday-Holiday Boardings'!J15 -> 34528 | ... DX15: ='Total Weekday Boardings'!DX15+'Total Saturday Boardings'!DX15+'Total Sunday-Holiday Boardings'!DX15 -> 33288 | DY15: 33560 | DZ15: 37004 | EA15: 36559 | EB15: 40946 | EC15: 37386 | ED15: 35104 | EE15: 37348 | EF15: 38657 | EG15: 29728 | EH15: 17128 | EI15: 16868 | EJ15: 15885 | EK15: 15001 | EL15: 14818 | EM15: 16029 | EN15: 16566 | EO15: 14548 | EP15: 11503 | EQ15: 6623 | ER15: 12395 | ES15: 14408 | ET15: 15771 | EU15: 14435 | EV15: 14796 | EW15: 14548 | EX15: 16840 | EY15: 16988 | EZ15: 18634 | FA15: 20285 | FB15: 18347 | FC15: 16511 | FD15: 19280 | FE15: 22876 | FF15: 21141 | FG15: =SUM('Total Weekday Boardings'!FG15,'Total Saturday Boardings'!FG15,'Total Sunday-Holiday Boardings'!FG15) -> 19841 | FH15: =SUM('Total Weekday Boardings'!FH15,'Total Saturday Boardings'!FH15,'Total Sunday-Holiday Boardings'!FH15) -> 15945 | FI15: =SUM('Total Weekday Boardings'!FI15,'Total Saturday Boardings'!FI15,'Total Sunday-Holiday Boardings'!FI15) -> 16161 | FJ15: =SUM('Total Weekday Boardings'!FJ15,'Total Saturday Boardings'!FJ15,'Total Sunday-Holiday Boardings'!FJ15) -> 18101 | FK15: =SUM('Total Weekday Boardings'!FK15,'Total Saturday Boardings'!FK15,'Total Sunday-Holiday Boardings'!FK15) -> 21218 | FL15: =SUM('Total Weekday Boardings'!FL15,'Total Saturday Boardings'!FL15,'Total Sunday-Holiday Boardings'!FL15) -> 22712 | FM15: =SUM('Total Weekday Boardings'!FM15,'Total Saturday Boardings'!FM15,'Total Sunday-Holiday Boardings'!FM15) -> 19152 | FN15: =SUM('Total Weekday Boardings'!FN15,'Total Saturday Boardings'!FN15,'Total Sunday-Holiday Boardings'!FN15) -> 19063 | ... FT15: =SUM('Total Weekday Boardings'!FT15,'Total Saturday Boardings'!FT15,'Total Sunday-Holiday Boardings'!FT15) -> 20765 | FU15: 21788 | FV15: 24170 | FW15: 21912 | FX15: 25526 | FY15: 22907 | FZ15: 22537 | GA15: 23649 | GB15: 26201 | GC15: 26961 | GD15: 24458 | GE15: 24439 | GF15: 21572 | GG15: 22946 | GH15: 23660 | GI15: 23233 | GJ15: 25244 | GK15: 21798 | GL15: 21314
A16: Osborn/Central Ave | C16: ='Total Weekday Boardings'!C16+'Total Saturday Boardings'!C16+'Total Sunday-Holiday Boardings'!C16 -> 21932 | D16: ='Total Weekday Boardings'!D16+'Total Saturday Boardings'!D16+'Total Sunday-Holiday Boardings'!D16 -> 22713 | E16: ='Total Weekday Boardings'!E16+'Total Saturday Boardings'!E16+'Total Sunday-Holiday Boardings'!E16 -> 22446 | F16: ='Total Weekday Boardings'!F16+'Total Saturday Boardings'!F16+'Total Sunday-Holiday Boardings'!F16 -> 23329 | G16: ='Total Weekday Boardings'!G16+'Total Saturday Boardings'!G16+'Total Sunday-Holiday Boardings'!G16 -> 21887 | H16: ='Total Weekday Boardings'!H16+'Total Saturday Boardings'!H16+'Total Sunday-Holiday Boardings'!H16 -> 17069 | I16: ='Total Weekday Boardings'!I16+'Total Saturday Boardings'!I16+'Total Sunday-Holiday Boardings'!I16 -> 17823 | J16: ='Total Weekday Boardings'!J16+'Total Saturday Boardings'!J16+'Total Sunday-Holiday Boardings'!J16 -> 20423 | ... DX16: ='Total Weekday Boardings'!DX16+'Total Saturday Boardings'!DX16+'Total Sunday-Holiday Boardings'!DX16 -> 21000 | DY16: 20660 | DZ16: 22731 | EA16: 22990 | EB16: 24941 | EC16: 22447 | ED16: 21195 | EE16: 21862 | EF16: 22049 | EG16: 17391 | EH16: 10353 | EI16: 11105 | EJ16: 10467 | EK16: 10316 | EL16: 10156 | EM16: 10163 | EN16: 10358 | EO16: 9859 | EP16: 7286 | EQ16: 4002 | ER16: 7871 | ES16: 9231 | ET16: 10040 | EU16: 9705 | EV16: 9936 | EW16: 9859 | EX16: 10979 | EY16: 10204 | EZ16: 10509 | FA16: 10819 | FB16: 10835 | FC16: 9779 | FD16: 10620 | FE16: 12618 | FF16: 12161 | FG16: =SUM('Total Weekday Boardings'!FG16,'Total Saturday Boardings'!FG16,'Total Sunday-Holiday Boardings'!FG16) -> 11895 | FH16: =SUM('Total Weekday Boardings'!FH16,'Total Saturday Boardings'!FH16,'Total Sunday-Holiday Boardings'!FH16) -> 9667 | FI16: =SUM('Total Weekday Boardings'!FI16,'Total Saturday Boardings'!FI16,'Total Sunday-Holiday Boardings'!FI16) -> 9426 | FJ16: =SUM('Total Weekday Boardings'!FJ16,'Total Saturday Boardings'!FJ16,'Total Sunday-Holiday Boardings'!FJ16) -> 10460 | FK16: =SUM('Total Weekday Boardings'!FK16,'Total Saturday Boardings'!FK16,'Total Sunday-Holiday Boardings'!FK16) -> 11203.75 | FL16: =SUM('Total Weekday Boardings'!FL16,'Total Saturday Boardings'!FL16,'Total Sunday-Holiday Boardings'!FL16) -> 11371 | FM16: =SUM('Total Weekday Boardings'!FM16,'Total Saturday Boardings'!FM16,'Total Sunday-Holiday Boardings'!FM16) -> 10647 | FN16: =SUM('Total Weekday Boardings'!FN16,'Total Saturday Boardings'!FN16,'Total Sunday-Holiday Boardings'!FN16) -> 10534 | ... FT16: =SUM('Total Weekday Boardings'!FT16,'Total Saturday Boardings'!FT16,'Total Sunday-Holiday Boardings'!FT16) -> 13091 | FU16: 13125 | FV16: 13923 | FW16: 11971 | FX16: 13410 | FY16: 12488 | FZ16: 12805 | GA16: 13866 | GB16: 13438 | GC16: 13735 | GD16: 13281 | GE16: 13526 | GF16: 12513 | GG16: 12695 | GH16: 13989 | GI16: 13213 | GJ16: 13987 | GK16: 12955 | GL16: 12269
A17: Thomas/Central Ave | C17: ='Total Weekday Boardings'!C17+'Total Saturday Boardings'!C17+'Total Sunday-Holiday Boardings'!C17 -> 30405 | D17: ='Total Weekday Boardings'!D17+'Total Saturday Boardings'!D17+'Total Sunday-Holiday Boardings'!D17 -> 35455 | E17: ='Total Weekday Boardings'!E17+'Total Saturday Boardings'!E17+'Total Sunday-Holiday Boardings'!E17 -> 34801 | F17: ='Total Weekday Boardings'!F17+'Total Saturday Boardings'!F17+'Total Sunday-Holiday Boardings'!F17 -> 37805 | G17: ='Total Weekday Boardings'!G17+'Total Saturday Boardings'!G17+'Total Sunday-Holiday Boardings'!G17 -> 35396 | H17: ='Total Weekday Boardings'!H17+'Total Saturday Boardings'!H17+'Total Sunday-Holiday Boardings'!H17 -> 33424 | I17: ='Total Weekday Boardings'!I17+'Total Saturday Boardings'!I17+'Total Sunday-Holiday Boardings'!I17 -> 32186 | J17: ='Total Weekday Boardings'!J17+'Total Saturday Boardings'!J17+'Total Sunday-Holiday Boardings'!J17 -> 35040 | ... DX17: ='Total Weekday Boardings'!DX17+'Total Saturday Boardings'!DX17+'Total Sunday-Holiday Boardings'!DX17 -> 37369 | DY17: 35890 | DZ17: 41945 | EA17: 40448 | EB17: 43561 | EC17: 40415 | ED17: 36302 | EE17: 38586 | EF17: 39159 | EG17: 29949 | EH17: 16843 | EI17: 16659 | EJ17: 16688 | EK17: 14877 | EL17: 15388 | EM17: 15479 | EN17: 16730 | EO17: 17266 | EP17: 11996 | EQ17: 6604 | ER17: 13046 | ES17: 15318 | ET17: 17284 | EU17: 16233 | EV17: 17110 | EW17: 17266 | EX17: 19821 | EY17: 19514 | EZ17: 20388 | FA17: 20906 | FB17: 20078 | FC17: 18429 | FD17: 21365 | FE17: 26247 | FF17: 24853 | FG17: =SUM('Total Weekday Boardings'!FG17,'Total Saturday Boardings'!FG17,'Total Sunday-Holiday Boardings'!FG17) -> 22203 | FH17: =SUM('Total Weekday Boardings'!FH17,'Total Saturday Boardings'!FH17,'Total Sunday-Holiday Boardings'!FH17) -> 17315 | FI17: =SUM('Total Weekday Boardings'!FI17,'Total Saturday Boardings'!FI17,'Total Sunday-Holiday Boardings'!FI17) -> 18371 | FJ17: =SUM('Total Weekday Boardings'!FJ17,'Total Saturday Boardings'!FJ17,'Total Sunday-Holiday Boardings'!FJ17) -> 21175 | FK17: =SUM('Total Weekday Boardings'!FK17,'Total Saturday Boardings'!FK17,'Total Sunday-Holiday Boardings'!FK17) -> 22856.25 | FL17: =SUM('Total Weekday Boardings'!FL17,'Total Saturday Boardings'!FL17,'Total Sunday-Holiday Boardings'!FL17) -> 23058 | FM17: =SUM('Total Weekday Boardings'!FM17,'Total Saturday Boardings'!FM17,'Total Sunday-Holiday Boardings'!FM17) -> 21454 | FN17: =SUM('Total Weekday Boardings'!FN17,'Total Saturday Boardings'!FN17,'Total Sunday-Holiday Boardings'!FN17) -> 20659 | ... FT17: =SUM('Total Weekday Boardings'!FT17,'Total Saturday Boardings'!FT17,'Total Sunday-Holiday Boardings'!FT17) -> 24081 | FU17: 21771 | FV17: 24113 | FW17: 23384 | FX17: 26710 | FY17: 24634 | FZ17: 23450 | GA17: 25874 | GB17: 26931 | GC17: 27739 | GD17: 26991 | GE17: 27393 | GF17: 24332 | GG17: 24045 | GH17: 26956 | GI17: 26786 | GJ17: 27730 | GK17: 24314 | GL17: 22597
A18: Encanto/Central Ave | C18: ='Total Weekday Boardings'!C18+'Total Saturday Boardings'!C18+'Total Sunday-Holiday Boardings'!C18 -> 12729 | D18: ='Total Weekday Boardings'!D18+'Total Saturday Boardings'!D18+'Total Sunday-Holiday Boardings'!D18 -> 15187 | E18: ='Total Weekday Boardings'!E18+'Total Saturday Boardings'!E18+'Total Sunday-Holiday Boardings'!E18 -> 17572 | F18: ='Total Weekday Boardings'!F18+'Total Saturday Boardings'!F18+'Total Sunday-Holiday Boardings'!F18 -> 15762 | G18: ='Total Weekday Boardings'!G18+'Total Saturday Boardings'!G18+'Total Sunday-Holiday Boardings'!G18 -> 13224 | H18: ='Total Weekday Boardings'!H18+'Total Saturday Boardings'!H18+'Total Sunday-Holiday Boardings'!H18 -> 11865 | I18: ='Total Weekday Boardings'!I18+'Total Saturday Boardings'!I18+'Total Sunday-Holiday Boardings'!I18 -> 11153 | J18: ='Total Weekday Boardings'!J18+'Total Saturday Boardings'!J18+'Total Sunday-Holiday Boardings'!J18 -> 12601 | ... DX18: ='Total Weekday Boardings'!DX18+'Total Saturday Boardings'!DX18+'Total Sunday-Holiday Boardings'!DX18 -> 11986 | DY18: 11123 | DZ18: 13006 | EA18: 12507 | EB18: 14143 | EC18: 13812 | ED18: 12262 | EE18: 13467 | EF18: 13684 | EG18: 10637 | EH18: 5100 | EI18: 5398 | EJ18: 4829 | EK18: 4799 | EL18: 4928 | EM18: 5462 | EN18: 5704 | EO18: 5770 | EP18: 4312 | EQ18: 2473 | ER18: 4470 | ES18: 5536 | ET18: 6140 | EU18: 5507 | EV18: 5815 | EW18: 5770 | EX18: 6434 | EY18: 5962 | EZ18: 6350 | FA18: 6840 | FB18: 6648 | FC18: 5490 | FD18: 6505 | FE18: 8966 | FF18: 7385 | FG18: =SUM('Total Weekday Boardings'!FG18,'Total Saturday Boardings'!FG18,'Total Sunday-Holiday Boardings'!FG18) -> 6895 | FH18: =SUM('Total Weekday Boardings'!FH18,'Total Saturday Boardings'!FH18,'Total Sunday-Holiday Boardings'!FH18) -> 5452 | FI18: =SUM('Total Weekday Boardings'!FI18,'Total Saturday Boardings'!FI18,'Total Sunday-Holiday Boardings'!FI18) -> 5349 | FJ18: =SUM('Total Weekday Boardings'!FJ18,'Total Saturday Boardings'!FJ18,'Total Sunday-Holiday Boardings'!FJ18) -> 6342 | FK18: =SUM('Total Weekday Boardings'!FK18,'Total Saturday Boardings'!FK18,'Total Sunday-Holiday Boardings'!FK18) -> 6657.5 | FL18: =SUM('Total Weekday Boardings'!FL18,'Total Saturday Boardings'!FL18,'Total Sunday-Holiday Boardings'!FL18) -> 6562 | FM18: =SUM('Total Weekday Boardings'!FM18,'Total Saturday Boardings'!FM18,'Total Sunday-Holiday Boardings'!FM18) -> 6329 | FN18: =SUM('Total Weekday Boardings'!FN18,'Total Saturday Boardings'!FN18,'Total Sunday-Holiday Boardings'!FN18) -> 6313 | ... FT18: =SUM('Total Weekday Boardings'!FT18,'Total Saturday Boardings'!FT18,'Total Sunday-Holiday Boardings'!FT18) -> 7584 | FU18: 6739 | FV18: 7242 | FW18: 7282 | FX18: 9095 | FY18: 7979 | FZ18: 7757 | GA18: 8201 | GB18: 8652 | GC18: 9547 | GD18: 8506 | GE18: 7946 | GF18: 7393 | GG18: 7209 | GH18: 7908 | GI18: 8225 | GJ18: 8783 | GK18: 7926 | GL18: 7346
A19: McDowell/Central Ave | C19: ='Total Weekday Boardings'!C19+'Total Saturday Boardings'!C19+'Total Sunday-Holiday Boardings'!C19 -> 35951 | D19: ='Total Weekday Boardings'!D19+'Total Saturday Boardings'!D19+'Total Sunday-Holiday Boardings'!D19 -> 40693 | E19: ='Total Weekday Boardings'!E19+'Total Saturday Boardings'!E19+'Total Sunday-Holiday Boardings'!E19 -> 37506 | F19: ='Total Weekday Boardings'!F19+'Total Saturday Boardings'!F19+'Total Sunday-Holiday Boardings'!F19 -> 29292 | G19: ='Total Weekday Boardings'!G19+'Total Saturday Boardings'!G19+'Total Sunday-Holiday Boardings'!G19 -> 41376 | H19: ='Total Weekday Boardings'!H19+'Total Saturday Boardings'!H19+'Total Sunday-Holiday Boardings'!H19 -> 31923 | I19: ='Total Weekday Boardings'!I19+'Total Saturday Boardings'!I19+'Total Sunday-Holiday Boardings'!I19 -> 39523 | J19: ='Total Weekday Boardings'!J19+'Total Saturday Boardings'!J19+'Total Sunday-Holiday Boardings'!J19 -> 46240 | ... DX19: ='Total Weekday Boardings'!DX19+'Total Saturday Boardings'!DX19+'Total Sunday-Holiday Boardings'!DX19 -> 39712 | DY19: 38501 | DZ19: 42943 | EA19: 43655 | EB19: 47587 | EC19: 42077 | ED19: 38341 | EE19: 41951 | EF19: 41532 | EG19: 30183 | EH19: 14821 | EI19: 14989 | EJ19: 14500 | EK19: 12798 | EL19: 13387 | EM19: 13570 | EN19: 14905 | EO19: 16620 | EP19: 10641 | EQ19: 6134 | ER19: 12447 | ES19: 16094 | ET19: 14547 | EU19: 14341 | EV19: 15909 | EW19: 16620 | EX19: 19066 | EY19: 19492 | EZ19: 20873 | FA19: 20764 | FB19: 20094 | FC19: 18069 | FD19: 21603 | FE19: 25998 | FF19: 24276 | FG19: =SUM('Total Weekday Boardings'!FG19,'Total Saturday Boardings'!FG19,'Total Sunday-Holiday Boardings'!FG19) -> 22549 | FH19: =SUM('Total Weekday Boardings'!FH19,'Total Saturday Boardings'!FH19,'Total Sunday-Holiday Boardings'!FH19) -> 18463 | FI19: =SUM('Total Weekday Boardings'!FI19,'Total Saturday Boardings'!FI19,'Total Sunday-Holiday Boardings'!FI19) -> 19370 | FJ19: =SUM('Total Weekday Boardings'!FJ19,'Total Saturday Boardings'!FJ19,'Total Sunday-Holiday Boardings'!FJ19) -> 22160 | FK19: =SUM('Total Weekday Boardings'!FK19,'Total Saturday Boardings'!FK19,'Total Sunday-Holiday Boardings'!FK19) -> 23589 | FL19: =SUM('Total Weekday Boardings'!FL19,'Total Saturday Boardings'!FL19,'Total Sunday-Holiday Boardings'!FL19) -> 24132 | FM19: =SUM('Total Weekday Boardings'!FM19,'Total Saturday Boardings'!FM19,'Total Sunday-Holiday Boardings'!FM19) -> 21479 | FN19: =SUM('Total Weekday Boardings'!FN19,'Total Saturday Boardings'!FN19,'Total Sunday-Holiday Boardings'!FN19) -> 21524 | ... FT19: =SUM('Total Weekday Boardings'!FT19,'Total Saturday Boardings'!FT19,'Total Sunday-Holiday Boardings'!FT19) -> 24706 | FU19: 23825 | FV19: 26265 | FW19: 25314 | FX19: 28279 | FY19: 25334 | FZ19: 24173 | GA19: 26786 | GB19: 28326 | GC19: 29525 | GD19: 29857 | GE19: 29271 | GF19: 29424 | GG19: 30337 | GH19: 32127 | GI19: 31109 | GJ19: 29470 | GK19: 24838 | GL19: 23703
A20: Roosevelt/Central Ave | C20: ='Total Weekday Boardings'!C20+'Total Saturday Boardings'!C20+'Total Sunday-Holiday Boardings'!C20 -> 18837 | D20: ='Total Weekday Boardings'!D20+'Total Saturday Boardings'!D20+'Total Sunday-Holiday Boardings'!D20 -> 33356 | E20: ='Total Weekday Boardings'!E20+'Total Saturday Boardings'!E20+'Total Sunday-Holiday Boardings'!E20 -> 39638 | F20: ='Total Weekday Boardings'!F20+'Total Saturday Boardings'!F20+'Total Sunday-Holiday Boardings'!F20 -> 46434 | G20: ='Total Weekday Boardings'!G20+'Total Saturday Boardings'!G20+'Total Sunday-Holiday Boardings'!G20 -> 35686 | H20: ='Total Weekday Boardings'!H20+'Total Saturday Boardings'!H20+'Total Sunday-Holiday Boardings'!H20 -> 38323 | I20: ='Total Weekday Boardings'!I20+'Total Saturday Boardings'!I20+'Total Sunday-Holiday Boardings'!I20 -> 45232 | J20: ='Total Weekday Boardings'!J20+'Total Saturday Boardings'!J20+'Total Sunday-Holiday Boardings'!J20 -> 52972 | ... DX20: ='Total Weekday Boardings'!DX20+'Total Saturday Boardings'!DX20+'Total Sunday-Holiday Boardings'!DX20 -> 23649 | DY20: 21663 | DZ20: 24752 | EA20: 24525 | EB20: 26826 | EC20: 26230 | ED20: 23766 | EE20: 26463 | EF20: 26185 | EG20: 21500 | EH20: 10665 | EI20: 11159 | EJ20: 9911 | EK20: 9365 | EL20: 10033 | EM20: 10441 | EN20: 11253 | EO20: 12425 | EP20: 8647 | EQ20: 4782 | ER20: 9147 | ES20: 10989 | ET20: 11793 | EU20: 11909 | EV20: 12384 | EW20: 12425 | EX20: 13678 | EY20: 13638 | EZ20: 15033 | FA20: 14471 | FB20: 14730 | FC20: 12902 | FD20: 15867 | FE20: 21059 | FF20: 23478 | FG20: =SUM('Total Weekday Boardings'!FG20,'Total Saturday Boardings'!FG20,'Total Sunday-Holiday Boardings'!FG20) -> 22103 | FH20: =SUM('Total Weekday Boardings'!FH20,'Total Saturday Boardings'!FH20,'Total Sunday-Holiday Boardings'!FH20) -> 15019 | FI20: =SUM('Total Weekday Boardings'!FI20,'Total Saturday Boardings'!FI20,'Total Sunday-Holiday Boardings'!FI20) -> 13462 | FJ20: =SUM('Total Weekday Boardings'!FJ20,'Total Saturday Boardings'!FJ20,'Total Sunday-Holiday Boardings'!FJ20) -> 15035 | FK20: =SUM('Total Weekday Boardings'!FK20,'Total Saturday Boardings'!FK20,'Total Sunday-Holiday Boardings'!FK20) -> 16842.75 | FL20: =SUM('Total Weekday Boardings'!FL20,'Total Saturday Boardings'!FL20,'Total Sunday-Holiday Boardings'!FL20) -> 16903 | FM20: =SUM('Total Weekday Boardings'!FM20,'Total Saturday Boardings'!FM20,'Total Sunday-Holiday Boardings'!FM20) -> 15718 | FN20: =SUM('Total Weekday Boardings'!FN20,'Total Saturday Boardings'!FN20,'Total Sunday-Holiday Boardings'!FN20) -> 15318 | ... FT20: =SUM('Total Weekday Boardings'!FT20,'Total Saturday Boardings'!FT20,'Total Sunday-Holiday Boardings'!FT20) -> 17986 | FU20: 16937 | FV20: 17628 | FW20: 17565 | FX20: 21342 | FY20: 19758 | FZ20: 19175 | GA20: 21501 | GB20: 20788 | GC20: 22413 | GD20: 24080 | GE20: 20357 | GF20: 19149 | GG20: 19115 | GH20: 20231 | GI20: 20054 | GJ20: 19959 | GK20: 18832 | GL20: 17279
A21: WB Van Buren/Central Ave | C21: ='Total Weekday Boardings'!C21+'Total Saturday Boardings'!C21+'Total Sunday-Holiday Boardings'!C21 -> 31903 | D21: ='Total Weekday Boardings'!D21+'Total Saturday Boardings'!D21+'Total Sunday-Holiday Boardings'!D21 -> 34623 | E21: ='Total Weekday Boardings'!E21+'Total Saturday Boardings'!E21+'Total Sunday-Holiday Boardings'!E21 -> 35357 | F21: ='Total Weekday Boardings'!F21+'Total Saturday Boardings'!F21+'Total Sunday-Holiday Boardings'!F21 -> 37488 | G21: ='Total Weekday Boardings'!G21+'Total Saturday Boardings'!G21+'Total Sunday-Holiday Boardings'!G21 -> 29496 | H21: ='Total Weekday Boardings'!H21+'Total Saturday Boardings'!H21+'Total Sunday-Holiday Boardings'!H21 -> 33290 | I21: ='Total Weekday Boardings'!I21+'Total Saturday Boardings'!I21+'Total Sunday-Holiday Boardings'!I21 -> 28068 | J21: ='Total Weekday Boardings'!J21+'Total Saturday Boardings'!J21+'Total Sunday-Holiday Boardings'!J21 -> 30392 | ... DX21: ='Total Weekday Boardings'!DX21+'Total Saturday Boardings'!DX21+'Total Sunday-Holiday Boardings'!DX21 -> 43128 | DY21: 43093 | DZ21: 50295 | EA21: 50908 | EB21: 53610 | EC21: 47009 | ED21: 40634 | EE21: 43981 | EF21: 43975 | EG21: 34190 | EH21: 19448 | EI21: 18846 | EJ21: 16917 | EK21: 16709 | EL21: 17543 | EM21: 17269 | EN21: 18711 | EO21: 16375 | EP21: 11615 | EQ21: 7243 | ER21: 6754 | ES21: 17256 | ET21: 16557 | EU21: 15806 | EV21: 16230 | EW21: 16375 | EX21: 19949 | EY21: 21026 | EZ21: 20905 | FA21: 20946 | FB21: 19416 | FC21: 18155 | FD21: 21499 | FE21: 25283 | FF21: 13421 | FG21: =SUM('Total Weekday Boardings'!FG21,'Total Saturday Boardings'!FG21,'Total Sunday-Holiday Boardings'!FG21) -> 18627 | FH21: =SUM('Total Weekday Boardings'!FH21,'Total Saturday Boardings'!FH21,'Total Sunday-Holiday Boardings'!FH21) -> 26579 | FI21: =SUM('Total Weekday Boardings'!FI21,'Total Saturday Boardings'!FI21,'Total Sunday-Holiday Boardings'!FI21) -> 17188 | FJ21: =SUM('Total Weekday Boardings'!FJ21,'Total Saturday Boardings'!FJ21,'Total Sunday-Holiday Boardings'!FJ21) -> 13898 | FK21: =SUM('Total Weekday Boardings'!FK21,'Total Saturday Boardings'!FK21,'Total Sunday-Holiday Boardings'!FK21) -> 16836.25 | FL21: =SUM('Total Weekday Boardings'!FL21,'Total Saturday Boardings'!FL21,'Total Sunday-Holiday Boardings'!FL21) -> 15716 | FM21: =SUM('Total Weekday Boardings'!FM21,'Total Saturday Boardings'!FM21,'Total Sunday-Holiday Boardings'!FM21) -> 14357 | FN21: =SUM('Total Weekday Boardings'!FN21,'Total Saturday Boardings'!FN21,'Total Sunday-Holiday Boardings'!FN21) -> 12026 | ... FT21: =SUM('Total Weekday Boardings'!FT21,'Total Saturday Boardings'!FT21,'Total Sunday-Holiday Boardings'!FT21) -> 13545 | FU21: 12952 | FV21: 22893 | FW21: 16057 | FX21: 17021 | FY21: 15847 | FZ21: 13341 | GA21: 13640 | GB21: 16281 | GC21: 15536 | GD21: 15125 | GE21: 14489 | GF21: 13063 | GG21: 13605 | GH21: 15869 | GI21: 16323 | GJ21: 16668 | GK21: 14679 | GL21: 12725
... A32: 44th St/Washington | C32: ='Total Weekday Boardings'!C32+'Total Saturday Boardings'!C32+'Total Sunday-Holiday Boardings'!C32 -> 36769 | D32: ='Total Weekday Boardings'!D32+'Total Saturday Boardings'!D32+'Total Sunday-Holiday Boardings'!D32 -> 41256 | E32: ='Total Weekday Boardings'!E32+'Total Saturday Boardings'!E32+'Total Sunday-Holiday Boardings'!E32 -> 39575 | F32: ='Total Weekday Boardings'!F32+'Total Saturday Boardings'!F32+'Total Sunday-Holiday Boardings'!F32 -> 47196 | G32: ='Total Weekday Boardings'!G32+'Total Saturday Boardings'!G32+'Total Sunday-Holiday Boardings'!G32 -> 37040 | H32: ='Total Weekday Boardings'!H32+'Total Saturday Boardings'!H32+'Total Sunday-Holiday Boardings'!H32 -> 43722 | I32: ='Total Weekday Boardings'!I32+'Total Saturday Boardings'!I32+'Total Sunday-Holiday Boardings'!I32 -> 35407 | J32: ='Total Weekday Boardings'!J32+'Total Saturday Boardings'!J32+'Total Sunday-Holiday Boardings'!J32 -> 39974 | ... DX32: ='Total Weekday Boardings'!DX32+'Total Saturday Boardings'!DX32+'Total Sunday-Holiday Boardings'!DX32 -> 50448 | DY32: 51534 | DZ32: 57692 | EA32: 51479 | EB32: 54947 | EC32: 51206 | ED32: 51321 | EE32: 52707 | EF32: 51645 | EG32: 41844 | EH32: 22947 | EI32: 22233 | EJ32: 21490 | EK32: 22419 | EL32: 23657 | EM32: 22795 | EN32: 24458 | EO32: 27239 | EP32: 18226 | EQ32: 10674 | ER32: 19270 | ES32: 24536 | ET32: 24240 | EU32: 24222 | EV32: 26195 | EW32: 27239 | EX32: 26452 | EY32: 26320 | EZ32: 29655 | FA32: 30719 | FB32: 30744 | FC32: 27328 | FD32: 30581 | FE32: 38267 | FF32: 33486 | FG32: =SUM('Total Weekday Boardings'!FG32,'Total Saturday Boardings'!FG32,'Total Sunday-Holiday Boardings'!FG32) -> 29600 | FH32: =SUM('Total Weekday Boardings'!FH32,'Total Saturday Boardings'!FH32,'Total Sunday-Holiday Boardings'!FH32) -> 24033 | FI32: =SUM('Total Weekday Boardings'!FI32,'Total Saturday Boardings'!FI32,'Total Sunday-Holiday Boardings'!FI32) -> 26944 | FJ32: =SUM('Total Weekday Boardings'!FJ32,'Total Saturday Boardings'!FJ32,'Total Sunday-Holiday Boardings'!FJ32) -> 27866 | FK32: =SUM('Total Weekday Boardings'!FK32,'Total Saturday Boardings'!FK32,'Total Sunday-Holiday Boardings'!FK32) -> 30072.5 | FL32: =SUM('Total Weekday Boardings'!FL32,'Total Saturday Boardings'!FL32,'Total Sunday-Holiday Boardings'!FL32) -> 31261 | FM32: =SUM('Total Weekday Boardings'!FM32,'Total Saturday Boardings'!FM32,'Total Sunday-Holiday Boardings'!FM32) -> 29317 | FN32: =SUM('Total Weekday Boardings'!FN32,'Total Saturday Boardings'!FN32,'Total Sunday-Holiday Boardings'!FN32) -> 29387 | ... FT32: =SUM('Total Weekday Boardings'!FT32,'Total Saturday Boardings'!FT32,'Total Sunday-Holiday Boardings'!FT32) -> 32505 | FU32: 32329 | FV32: 32944 | FW32: 32417 | FX32: 37786 | FY32: 34672 | FZ32: 36258 | GA32: 36800 | GB32: 36278 | GC32: 39287 | GD32: 36066 | GE32: 37790 | GF32: 37062 | GG32: 34977 | GH32: 35839 | GI32: 35457 | GJ32: 36527 | GK32: 35825 | GL32: 34225
A33: 50th St/Washington | DW33: ='Total Weekday Boardings'!DW33+'Total Saturday Boardings'!DW33+'Total Sunday-Holiday Boardings'!DW33 -> 6766 | DX33: ='Total Weekday Boardings'!DX33+'Total Saturday Boardings'!DX33+'Total Sunday-Holiday Boardings'!DX33 -> 6637 | DY33: 7444 | DZ33: 7744 | EA33: 8058 | EB33: 11386 | EC33: 11866 | ED33: 12760 | EE33: 12746 | EF33: 11510 | EG33: 9881 | EH33: 6633 | EI33: 6856 | EJ33: 6926 | EK33: 7089 | EL33: 6473 | EM33: 6448 | EN33: 7517 | EO33: 6568 | EP33: 4298 | EQ33: 3130 | ER33: 5520 | ES33: 4754 | ET33: 29342 | EU33: 5841 | EV33: 6149 | EW33: 6568 | EX33: 6962 | EY33: 6543 | EZ33: 6980 | FA33: 6711 | FB33: 6739 | FC33: 6129 | FD33: 6750 | FE33: 8424 | FF33: 7908 | FG33: =SUM('Total Weekday Boardings'!FG33,'Total Saturday Boardings'!FG33,'Total Sunday-Holiday Boardings'!FG33) -> 19677 | FH33: =SUM('Total Weekday Boardings'!FH33,'Total Saturday Boardings'!FH33,'Total Sunday-Holiday Boardings'!FH33) -> 6356 | FI33: =SUM('Total Weekday Boardings'!FI33,'Total Saturday Boardings'!FI33,'Total Sunday-Holiday Boardings'!FI33) -> 6620 | FJ33: =SUM('Total Weekday Boardings'!FJ33,'Total Saturday Boardings'!FJ33,'Total Sunday-Holiday Boardings'!FJ33) -> 6973 | FK33: =SUM('Total Weekday Boardings'!FK33,'Total Saturday Boardings'!FK33,'Total Sunday-Holiday Boardings'!FK33) -> 7693 | FL33: =SUM('Total Weekday Boardings'!FL33,'Total Saturday Boardings'!FL33,'Total Sunday-Holiday Boardings'!FL33) -> 7392 | FM33: =SUM('Total Weekday Boardings'!FM33,'Total Saturday Boardings'!FM33,'Total Sunday-Holiday Boardings'!FM33) -> 7009 | FN33: =SUM('Total Weekday Boardings'!FN33,'Total Saturday Boardings'!FN33,'Total Sunday-Holiday Boardings'!FN33) -> 7205 | ... FT33: =SUM('Total Weekday Boardings'!FT33,'Total Saturday Boardings'!FT33,'Total Sunday-Holiday Boardings'!FT33) -> 8694 | FU33: 8203 | FV33: 8723 | FW33: 8009 | FX33: 8522 | FY33: 7716 | FZ33: 7484 | GA33: 8660 | GB33: 8313 | GC33: 8602 | GD33: 8318 | GE33: 8361 | GF33: 7220 | GG33: 7244 | GH33: 7634 | GI33: 7936 | GJ33: 8652 | GK33: 10131 | GL33: 9642
A34: Priest Dr/Washington St | C34: ='Total Weekday Boardings'!C34+'Total Saturday Boardings'!C34+'Total Sunday-Holiday Boardings'!C34 -> 35088 | D34: ='Total Weekday Boardings'!D34+'Total Saturday Boardings'!D34+'Total Sunday-Holiday Boardings'!D34 -> 28484 | E34: ='Total Weekday Boardings'!E34+'Total Saturday Boardings'!E34+'Total Sunday-Holiday Boardings'!E34 -> 30207 | F34: ='Total Weekday Boardings'!F34+'Total Saturday Boardings'!F34+'Total Sunday-Holiday Boardings'!F34 -> 37992 | G34: ='Total Weekday Boardings'!G34+'Total Saturday Boardings'!G34+'Total Sunday-Holiday Boardings'!G34 -> 38863 | H34: ='Total Weekday Boardings'!H34+'Total Saturday Boardings'!H34+'Total Sunday-Holiday Boardings'!H34 -> 25864 | I34: ='Total Weekday Boardings'!I34+'Total Saturday Boardings'!I34+'Total Sunday-Holiday Boardings'!I34 -> 30723 | J34: ='Total Weekday Boardings'!J34+'Total Saturday Boardings'!J34+'Total Sunday-Holiday Boardings'!J34 -> 34128 | ... DX34: ='Total Weekday Boardings'!DX34+'Total Saturday Boardings'!DX34+'Total Sunday-Holiday Boardings'!DX34 -> 26389 | DY34: 26248 | DZ34: 28165 | EA34: 27877 | EB34: 32436 | EC34: 30753 | ED34: 27812 | EE34: 28010 | EF34: 28589 | EG34: 24397 | EH34: 15170 | EI34: 13965 | EJ34: 12460 | EK34: 12167 | EL34: 13064 | EM34: 12833 | EN34: 14643 | EO34: 13007 | EP34: 10697 | EQ34: 6133 | ER34: 11511 | ES34: 12942 | ET34: 13192 | EU34: 12292 | EV34: 12636 | EW34: 13007 | EX34: 13416 | EY34: 13900 | EZ34: 14325 | FA34: 14467 | FB34: 13935 | FC34: 12831 | FD34: 14681 | FE34: 17162 | FF34: 15593 | FG34: =SUM('Total Weekday Boardings'!FG34,'Total Saturday Boardings'!FG34,'Total Sunday-Holiday Boardings'!FG34) -> 14359 | FH34: =SUM('Total Weekday Boardings'!FH34,'Total Saturday Boardings'!FH34,'Total Sunday-Holiday Boardings'!FH34) -> 12063 | FI34: =SUM('Total Weekday Boardings'!FI34,'Total Saturday Boardings'!FI34,'Total Sunday-Holiday Boardings'!FI34) -> 13368 | FJ34: =SUM('Total Weekday Boardings'!FJ34,'Total Saturday Boardings'!FJ34,'Total Sunday-Holiday Boardings'!FJ34) -> 13407 | FK34: =SUM('Total Weekday Boardings'!FK34,'Total Saturday Boardings'!FK34,'Total Sunday-Holiday Boardings'!FK34) -> 14407.25 | FL34: =SUM('Total Weekday Boardings'!FL34,'Total Saturday Boardings'!FL34,'Total Sunday-Holiday Boardings'!FL34) -> 14944 | FM34: =SUM('Total Weekday Boardings'!FM34,'Total Saturday Boardings'!FM34,'Total Sunday-Holiday Boardings'!FM34) -> 14667 | FN34: =SUM('Total Weekday Boardings'!FN34,'Total Saturday Boardings'!FN34,'Total Sunday-Holiday Boardings'!FN34) -> 14796 | ... FT34: =SUM('Total Weekday Boardings'!FT34,'Total Saturday Boardings'!FT34,'Total Sunday-Holiday Boardings'!FT34) -> 17386 | FU34: 17362 | FV34: 18798 | FW34: 17011 | FX34: 19757 | FY34: 18219 | FZ34: 18586 | GA34: 18923 | GB34: 17890 | GC34: 19026 | GD34: 17802 | GE34: 16473 | GF34: 15419 | GG34: 16123 | GH34: 16749 | GI34: 16212 | GJ34: 16829 | GK34: 15107 | GL34: 13572
A35: Center Pkwy/Washington St | C35: ='Total Weekday Boardings'!C35+'Total Saturday Boardings'!C35+'Total Sunday-Holiday Boardings'!C35 -> 9513 | D35: ='Total Weekday Boardings'!D35+'Total Saturday Boardings'!D35+'Total Sunday-Holiday Boardings'!D35 -> 9300 | E35: ='Total Weekday Boardings'!E35+'Total Saturday Boardings'!E35+'Total Sunday-Holiday Boardings'!E35 -> 6722 | F35: ='Total Weekday Boardings'!F35+'Total Saturday Boardings'!F35+'Total Sunday-Holiday Boardings'!F35 -> 4835 | G35: ='Total Weekday Boardings'!G35+'Total Saturday Boardings'!G35+'Total Sunday-Holiday Boardings'!G35 -> 8110 | H35: ='Total Weekday Boardings'!H35+'Total Saturday Boardings'!H35+'Total Sunday-Holiday Boardings'!H35 -> 7026 | I35: ='Total Weekday Boardings'!I35+'Total Saturday Boardings'!I35+'Total Sunday-Holiday Boardings'!I35 -> 7625 | J35: ='Total Weekday Boardings'!J35+'Total Saturday Boardings'!J35+'Total Sunday-Holiday Boardings'!J35 -> 6903 | ... DX35: ='Total Weekday Boardings'!DX35+'Total Saturday Boardings'!DX35+'Total Sunday-Holiday Boardings'!DX35 -> 6179 | DY35: 5940 | DZ35: 9252 | EA35: 7058 | EB35: 8533 | EC35: 8579 | ED35: 7283 | EE35: 7710 | EF35: 8114 | EG35: 6683 | EH35: 4350 | EI35: 5003 | EJ35: 4265 | EK35: 3783 | EL35: 4124 | EM35: 4407 | EN35: 4654 | EO35: 3964 | EP35: 3978 | EQ35: 2272 | ER35: 3760 | ES35: 4581 | ET35: 4335 | EU35: 3503 | EV35: 3859 | EW35: 3964 | EX35: 4303 | EY35: 4926 | EZ35: 5129 | FA35: 4739 | FB35: 4217 | FC35: 4151 | FD35: 4507 | FE35: 5879 | FF35: 5723 | FG35: =SUM('Total Weekday Boardings'!FG35,'Total Saturday Boardings'!FG35,'Total Sunday-Holiday Boardings'!FG35) -> 5083 | FH35: =SUM('Total Weekday Boardings'!FH35,'Total Saturday Boardings'!FH35,'Total Sunday-Holiday Boardings'!FH35) -> 3563 | FI35: =SUM('Total Weekday Boardings'!FI35,'Total Saturday Boardings'!FI35,'Total Sunday-Holiday Boardings'!FI35) -> 4058 | FJ35: =SUM('Total Weekday Boardings'!FJ35,'Total Saturday Boardings'!FJ35,'Total Sunday-Holiday Boardings'!FJ35) -> 4695 | FK35: =SUM('Total Weekday Boardings'!FK35,'Total Saturday Boardings'!FK35,'Total Sunday-Holiday Boardings'!FK35) -> 5774 | FL35: =SUM('Total Weekday Boardings'!FL35,'Total Saturday Boardings'!FL35,'Total Sunday-Holiday Boardings'!FL35) -> 5052 | FM35: =SUM('Total Weekday Boardings'!FM35,'Total Saturday Boardings'!FM35,'Total Sunday-Holiday Boardings'!FM35) -> 4747 | FN35: =SUM('Total Weekday Boardings'!FN35,'Total Saturday Boardings'!FN35,'Total Sunday-Holiday Boardings'!FN35) -> 4588 | ... FT35: =SUM('Total Weekday Boardings'!FT35,'Total Saturday Boardings'!FT35,'Total Sunday-Holiday Boardings'!FT35) -> 5252 | FU35: 4630 | FV35: 5714 | FW35: 5331 | FX35: 6411 | FY35: 5782 | FZ35: 5022 | GA35: 5852 | GB35: 5740 | GC35: 5747 | GD35: 5013 | GE35: 4932 | GF35: 4447 | GG35: 4995 | GH35: 5455 | GI35: 5468 | GJ35: 5587 | GK35: 6067 | GL35: 4483
